Workbook

Sheet Inputs
A1: LAYER 0 - INPUTS (edit yellow; every layer downstream recomputes)
A3: GLOBAL
A4: gamma | B4: 2 | C4: base curve exponent
A5: m | B5: 1 | C5: steepness knob
A6: g | B6: =B4*B5 | C6: g = m*gamma (computed)
A7: Gfac | B7: =B6*(B6+1)/2 | C7: G = g(g+1)/2 gamma factor (computed)
A8: u_seam | B8: =LN(B6/(B6+1)) | C8: LN(g/(g+1)) - smooth-paste seam, S*=K*g/(g+1) (computed)
A9: V_atm | B9: =(1/(B6+1))*(B6/(B6+1))^B6 | C9: (1/(g+1))*(g/(g+1))^g - ATM value (computed)
A10: sigma_cal | B10: 0.7 | C10: vol the curve is CALIBRATED to
A11: RV | B11: 0.6 | C11: realized vol
A12: days_per_year | B12: 365
A13: fee_bps | B13: 2.5 | C13: taker fee
A14: hedge_exec_cost | B14: 0.01 | C14: imperfect hedge + execution, APR on hedge notional
A15: order_mgmt_cost | B15: 0.005 | C15: limit-order placement/updating, APR on hedge notional
A16: borrow_APR | B16: 0.06 | C16: financing on book above equity
A17: HLP_base_APR | B17: 0.1 | C17: yield if HLP-margined
A18: hedge_ratio | B18: 1 | C18: 1.00 = fully delta-hedged (loop closes); <1 leaves residual
A19: S_ref | B19: 100000 | C19: reference price
A20: margin_per_unit | B20: 100000 | C20: LAYER 3: $ margin per carved unit at close
A21: L0 | B21: 1 | C21: carved-slice scale
A22: open_notional_units | B22: 10 | C22: total open option notional, UNITS
A23: daily_turnover | B23: 0.3 | C23: traded / open notional per day
A25: PER-LP - each LP picks its OWN shape (the feedback)
A26: LP | B26: beta (impact) | C26: h (half-spread) | D26: equity $ | E26: uses HLP (1/0)
A27: LP-1 deep | B27: 2 | C27: 0.001 | D27: 1000000 | E27: 0
A28: LP-2 mid | B28: 5 | C28: 0.0015 | D28: 500000 | E28: 0
A29: LP-3 thin/tightest | B29: 10 | C29: 0.0008 | D29: 250000 | E29: 1
A31: GRID u = LN(S/K). u<u_seam = past the seam (value IS intrinsic). Delta transports AND reads back.
A32: u = ln(S/K) | B32: S/K | C32: V(u) SINGLE number | D32: Delta(u) log-delta | E32: regime | F32: q(u) units open
A33: -0.6 | B33: =EXP(A33) | C33: =IF(A33<Inputs!$B$8,1-EXP(A33),Inputs!$B$9*EXP(-Inputs!$B$6*A33)) | D33: =IF(A33<Inputs!$B$8,EXP(A33),Inputs!$B$6*C33) | E33: =IF(A33<Inputs!$B$8,"INTRINSIC (past seam)","continuation") | F33: =D33/SUM($D$33:$D$37)*Inputs!$B$22
A34: -0.3 | B34: =EXP(A34) | C34: =IF(A34<Inputs!$B$8,1-EXP(A34),Inputs!$B$9*EXP(-Inputs!$B$6*A34)) | D34: =IF(A34<Inputs!$B$8,EXP(A34),Inputs!$B$6*C34) | E34: =IF(A34<Inputs!$B$8,"INTRINSIC (past seam)","continuation") | F34: =D34/SUM($D$33:$D$37)*Inputs!$B$22
A35: 0 | B35: =EXP(A35) | C35: =IF(A35<Inputs!$B$8,1-EXP(A35),Inputs!$B$9*EXP(-Inputs!$B$6*A35)) | D35: =IF(A35<Inputs!$B$8,EXP(A35),Inputs!$B$6*C35) | E35: =IF(A35<Inputs!$B$8,"INTRINSIC (past seam)","continuation") | F35: =D35/SUM($D$33:$D$37)*Inputs!$B$22
A36: 0.3 | B36: =EXP(A36) | C36: =IF(A36<Inputs!$B$8,1-EXP(A36),Inputs!$B$9*EXP(-Inputs!$B$6*A36)) | D36: =IF(A36<Inputs!$B$8,EXP(A36),Inputs!$B$6*C36) | E36: =IF(A36<Inputs!$B$8,"INTRINSIC (past seam)","continuation") | F36: =D36/SUM($D$33:$D$37)*Inputs!$B$22
A37: 0.6 | B37: =EXP(A37) | C37: =IF(A37<Inputs!$B$8,1-EXP(A37),Inputs!$B$9*EXP(-Inputs!$B$6*A37)) | D37: =IF(A37<Inputs!$B$8,EXP(A37),Inputs!$B$6*C37) | E37: =IF(A37<Inputs!$B$8,"INTRINSIC (past seam)","continuation") | F37: =D37/SUM($D$33:$D$37)*Inputs!$B$22
A39: V is ONE number (total value incl. ITM via smooth-paste) - no intrinsic/extrinsic split anywhere.
A41: TRADER SIDE — shared perp wallets (clubs) + carve
A42: club_long_notional $ | B42: 4000000 | C42: all LONG perps aggregated into ONE shared wallet
A43: club_short_notional $ | B43: 3000000 | C43: all SHORT perps aggregated into ONE shared wallet
A44: club_margin_frac | B44: 0.2 | C44: equity posted per $ notional (1/leverage)
A45: carve_frac_long | B45: 0.25 | C45: fraction of the LONG club carved to back option positions
...

Sheet 1_Shapes
A1: LAYER 1a - PER-LP SHAPE MAP: each LP's own curve | beta(u)=beta*Delta^2 | h(u)=h*|Delta|
A3: u | B3: Delta(u) | C3: b1(u) | D3: b2(u) | E3: b3(u) | F3: h1(u) | G3: h2(u) | H3: h3(u)
A4: =Inputs!A33 | B4: =Inputs!D33 | C4: =Inputs!$B$27*$B4^2 | D4: =Inputs!$B$28*$B4^2 | E4: =Inputs!$B$29*$B4^2 | F4: =Inputs!$C$27*ABS($B4) | G4: =Inputs!$C$28*ABS($B4) | H4: =Inputs!$C$29*ABS($B4)
A5: =Inputs!A34 | B5: =Inputs!D34 | C5: =Inputs!$B$27*$B5^2 | D5: =Inputs!$B$28*$B5^2 | E5: =Inputs!$B$29*$B5^2 | F5: =Inputs!$C$27*ABS($B5) | G5: =Inputs!$C$28*ABS($B5) | H5: =Inputs!$C$29*ABS($B5)
A6: =Inputs!A35 | B6: =Inputs!D35 | C6: =Inputs!$B$27*$B6^2 | D6: =Inputs!$B$28*$B6^2 | E6: =Inputs!$B$29*$B6^2 | F6: =Inputs!$C$27*ABS($B6) | G6: =Inputs!$C$28*ABS($B6) | H6: =Inputs!$C$29*ABS($B6)
A7: =Inputs!A36 | B7: =Inputs!D36 | C7: =Inputs!$B$27*$B7^2 | D7: =Inputs!$B$28*$B7^2 | E7: =Inputs!$B$29*$B7^2 | F7: =Inputs!$C$27*ABS($B7) | G7: =Inputs!$C$28*ABS($B7) | H7: =Inputs!$C$29*ABS($B7)
A8: =Inputs!A37 | B8: =Inputs!D37 | C8: =Inputs!$B$27*$B8^2 | D8: =Inputs!$B$28*$B8^2 | E8: =Inputs!$B$29*$B8^2 | F8: =Inputs!$C$27*ABS($B8) | G8: =Inputs!$C$28*ABS($B8) | H8: =Inputs!$C$29*ABS($B8)

Sheet 2_Aggregate
A1: LAYER 1b - AGGREGATION: N LP curves -> ONE book | 1/b_agg=sum(1/bi) | spread=tightest | shares strike-INVARIANT
A3: u | B3: 1/b1 | C3: 1/b2 | D3: 1/b3 | E3: sum 1/b | F3: b_agg | G3: h_agg (min) | H3: w1 | I3: w2 | J3: w3
A4: ='1_Shapes'!A4 | B4: =1/'1_Shapes'!C4 | C4: =1/'1_Shapes'!D4 | D4: =1/'1_Shapes'!E4 | E4: =SUM(B4:D4) | F4: =1/E4 | G4: =MIN('1_Shapes'!F4:H4) | H4: =B4/$E4 | I4: =C4/$E4 | J4: =D4/$E4
A5: ='1_Shapes'!A5 | B5: =1/'1_Shapes'!C5 | C5: =1/'1_Shapes'!D5 | D5: =1/'1_Shapes'!E5 | E5: =SUM(B5:D5) | F5: =1/E5 | G5: =MIN('1_Shapes'!F5:H5) | H5: =B5/$E5 | I5: =C5/$E5 | J5: =D5/$E5
A6: ='1_Shapes'!A6 | B6: =1/'1_Shapes'!C6 | C6: =1/'1_Shapes'!D6 | D6: =1/'1_Shapes'!E6 | E6: =SUM(B6:D6) | F6: =1/E6 | G6: =MIN('1_Shapes'!F6:H6) | H6: =B6/$E6 | I6: =C6/$E6 | J6: =D6/$E6
A7: ='1_Shapes'!A7 | B7: =1/'1_Shapes'!C7 | C7: =1/'1_Shapes'!D7 | D7: =1/'1_Shapes'!E7 | E7: =SUM(B7:D7) | F7: =1/E7 | G7: =MIN('1_Shapes'!F7:H7) | H7: =B7/$E7 | I7: =C7/$E7 | J7: =D7/$E7
A8: ='1_Shapes'!A8 | B8: =1/'1_Shapes'!C8 | C8: =1/'1_Shapes'!D8 | D8: =1/'1_Shapes'!E8 | E8: =SUM(B8:D8) | F8: =1/E8 | G8: =MIN('1_Shapes'!F8:H8) | H8: =B8/$E8 | I8: =C8/$E8 | J8: =D8/$E8
A10: CHECK shares identical across strikes (Delta^2 cancels): | H10: =MAX(H4:H8)-MIN(H4:H8) | I10: =MAX(I4:I8)-MIN(I4:I8) | J10: =MAX(J4:J8)-MIN(J4:J8)

Sheet 3_Portfolio
A1: LAYER 2 - PORTFOLIO ACCOUNTING: the curve gives TOTAL value in ONE number (ITM via smooth-paste; no intrinsic/extrinsic)
A3: u | B3: S/K | C3: V(u) total value | D3: regime | E3: q(u) units | F3: position value $ (q*V*S)
A4: =Inputs!A33 | B4: =Inputs!B33 | C4: =Inputs!C33 | D4: =Inputs!E33 | E4: =Inputs!F33 | F4: =C4*E4*Inputs!$B$19
A5: =Inputs!A34 | B5: =Inputs!B34 | C5: =Inputs!C34 | D5: =Inputs!E34 | E5: =Inputs!F34 | F5: =C5*E5*Inputs!$B$19
A6: =Inputs!A35 | B6: =Inputs!B35 | C6: =Inputs!C35 | D6: =Inputs!E35 | E6: =Inputs!F35 | F6: =C6*E6*Inputs!$B$19
A7: =Inputs!A36 | B7: =Inputs!B36 | C7: =Inputs!C36 | D7: =Inputs!E36 | E7: =Inputs!F36 | F7: =C7*E7*Inputs!$B$19
A8: =Inputs!A37 | B8: =Inputs!B37 | C8: =Inputs!C37 | D8: =Inputs!E37 | E8: =Inputs!F37 | F8: =C8*E8*Inputs!$B$19
A10: TOTAL book $ | F10: =SUM(F4:F8)
A12: Seam check: at u<u_seam the value column IS 1-S/K (intrinsic); C1-welded, value>=intrinsic everywhere.

Sheet 4_Trade
A1: LAYER 1c - TRADE & FILLS: volume split by the strike-invariant shares
A3: u | B3: q(u) units | C3: traded $/day | D3: q1 units | E3: q2 units | F3: q3 units | G3: fill$1/day | H3: fill$2/day | I3: fill$3/day
A4: =Inputs!A33 | B4: =Inputs!F33 | C4: =B4*Inputs!$B$19*Inputs!$B$23 | D4: =$B4*'2_Aggregate'!H4 | E4: =$B4*'2_Aggregate'!I4 | F4: =$B4*'2_Aggregate'!J4 | G4: =$C4*'2_Aggregate'!H4 | H4: =$C4*'2_Aggregate'!I4 | I4: =$C4*'2_Aggregate'!J4
A5: =Inputs!A34 | B5: =Inputs!F34 | C5: =B5*Inputs!$B$19*Inputs!$B$23 | D5: =$B5*'2_Aggregate'!H5 | E5: =$B5*'2_Aggregate'!I5 | F5: =$B5*'2_Aggregate'!J5 | G5: =$C5*'2_Aggregate'!H5 | H5: =$C5*'2_Aggregate'!I5 | I5: =$C5*'2_Aggregate'!J5
A6: =Inputs!A35 | B6: =Inputs!F35 | C6: =B6*Inputs!$B$19*Inputs!$B$23 | D6: =$B6*'2_Aggregate'!H6 | E6: =$B6*'2_Aggregate'!I6 | F6: =$B6*'2_Aggregate'!J6 | G6: =$C6*'2_Aggregate'!H6 | H6: =$C6*'2_Aggregate'!I6 | I6: =$C6*'2_Aggregate'!J6
A7: =Inputs!A36 | B7: =Inputs!F36 | C7: =B7*Inputs!$B$19*Inputs!$B$23 | D7: =$B7*'2_Aggregate'!H7 | E7: =$B7*'2_Aggregate'!I7 | F7: =$B7*'2_Aggregate'!J7 | G7: =$C7*'2_Aggregate'!H7 | H7: =$C7*'2_Aggregate'!I7 | I7: =$C7*'2_Aggregate'!J7
A8: =Inputs!A37 | B8: =Inputs!F37 | C8: =B8*Inputs!$B$19*Inputs!$B$23 | D8: =$B8*'2_Aggregate'!H8 | E8: =$B8*'2_Aggregate'!I8 | F8: =$B8*'2_Aggregate'!J8 | G8: =$C8*'2_Aggregate'!H8 | H8: =$C8*'2_Aggregate'!I8 | I8: =$C8*'2_Aggregate'!J8
A10: TOTAL | C10: =SUM(C4:C8) | G10: =SUM(G4:G8) | H10: =SUM(H4:H8) | I10: =SUM(I4:I8)

Sheet 5_Economics
A1: LAYER 2b - LP ECONOMICS per LP: carry(sigma_cal) - vol cost(RV) + spread + fees - hedge - financing + HLP
A3: line ($/yr unless noted) | B3: LP-1 | C3: LP-2 | D3: LP-3 | E3: TOTAL
A4: book short $ (sum q_i*V*S) | B4: =SUMPRODUCT('4_Trade'!D4:D8,'3_Portfolio'!$C$4:$C$8)*Inputs!$B$19 | C4: =SUMPRODUCT('4_Trade'!E4:E8,'3_Portfolio'!$C$4:$C$8)*Inputs!$B$19 | D4: =SUMPRODUCT('4_Trade'!F4:F8,'3_Portfolio'!$C$4:$C$8)*Inputs!$B$19 | E4: =SUM(B4:D4)
A5: carry income = book*G*sigma_cal^2 | B5: =B4*Inputs!$B$7*Inputs!$B$10^2 | C5: =C4*Inputs!$B$7*Inputs!$B$10^2 | D5: =D4*Inputs!$B$7*Inputs!$B$10^2 | E5: =SUM(B5:D5)
A6: vol cost = -book*G*RV^2 | B6: =-B4*Inputs!$B$7*Inputs!$B$11^2 | C6: =-C4*Inputs!$B$7*Inputs!$B$11^2 | D6: =-D4*Inputs!$B$7*Inputs!$B$11^2 | E6: =SUM(B6:D6)
A7: spread income | B7: =SUMPRODUCT('2_Aggregate'!$G$4:$G$8,'4_Trade'!G4:G8)*Inputs!$B$12 | C7: =SUMPRODUCT('2_Aggregate'!$G$4:$G$8,'4_Trade'!H4:H8)*Inputs!$B$12 | D7: =SUMPRODUCT('2_Aggregate'!$G$4:$G$8,'4_Trade'!I4:I8)*Inputs!$B$12 | E7: =SUM(B7:D7)
A8: fee income | B8: =Inputs!$B$13/10000*'4_Trade'!G10*Inputs!$B$12 | C8: =Inputs!$B$13/10000*'4_Trade'!H10*Inputs!$B$12 | D8: =Inputs!$B$13/10000*'4_Trade'!I10*Inputs!$B$12 | E8: =SUM(B8:D8)
A9: hedge notional $ (Layer 3) | B9: ='7_Closure'!B7 | C9: ='7_Closure'!C7 | D9: ='7_Closure'!D7 | E9: =SUM(B9:D9)
A10: hedge+exec+order cost | B10: =-(Inputs!$B$14+Inputs!$B$15)*B9 | C10: =-(Inputs!$B$14+Inputs!$B$15)*C9 | D10: =-(Inputs!$B$14+Inputs!$B$15)*D9 | E10: =SUM(B10:D10)
A11: financing | B11: =-MAX(0,B4-Inputs!$D$27)*Inputs!$B$16 | C11: =-MAX(0,C4-Inputs!$D$28)*Inputs!$B$16 | D11: =-MAX(0,D4-Inputs!$D$29)*Inputs!$B$16 | E11: =SUM(B11:D11)
A12: HLP yield | B12: =IF(Inputs!$E$27=1,Inputs!$B$17*Inputs!$D$27,0) | C12: =IF(Inputs!$E$28=1,Inputs!$B$17*Inputs!$D$28,0) | D12: =IF(Inputs!$E$29=1,Inputs!$B$17*Inputs!$D$29,0) | E12: =SUM(B12:D12)
A13: NET $ / yr | B13: =SUM(B5:B8)+SUM(B10:B12) | C13: =SUM(C5:C8)+SUM(C10:C12) | D13: =SUM(D5:D8)+SUM(D10:D12) | E13: =SUM(B13:D13)
A14: equity $ | B14: =Inputs!$D$27 | C14: =Inputs!$D$28 | D14: =Inputs!$D$29 | E14: =SUM(B14:D14)
A15: NET APR | B15: =B13/B14 | C15: =C13/C14 | D15: =D13/D14 | E15: =E13/E14

Sheet 6_Margin
A1: LAYER 3 - PERP UNITS -> ACTUAL MARGIN: the one doorway (station 17)
A3: line | B3: LP-1 | C3: LP-2 | D3: LP-3 | E3: TOTAL
A4: net PERP UNITS (sum q_i*V) | B4: =SUMPRODUCT('4_Trade'!D4:D8,'3_Portfolio'!$C$4:$C$8) | C4: =SUMPRODUCT('4_Trade'!E4:E8,'3_Portfolio'!$C$4:$C$8) | D4: =SUMPRODUCT('4_Trade'!F4:F8,'3_Portfolio'!$C$4:$C$8) | E4: =SUM(B4:D4)
A5: x margin per unit $ | B5: =Inputs!$B$20 | C5: =Inputs!$B$20 | D5: =Inputs!$B$20
A6: x L0 | B6: =Inputs!$B$21 | C6: =Inputs!$B$21 | D6: =Inputs!$B$21
A7: =MARGIN / CASH $ (the doorway) | B7: =B4*B5*B6 | C7: =C4*C5*C6 | D7: =D4*D5*D6 | E7: =SUM(B7:D7)

Sheet 7_Closure
A1: LOOP CLOSURE - HEDGE READBACK: exposure = NetPerp + sum Delta(u)*q(u) -> back to the perp book
A3: line | B3: LP-1 | C3: LP-2 | D3: LP-3 | E3: TOTAL
A4: option delta (sum Delta*q_i) units | B4: =SUMPRODUCT('4_Trade'!D4:D8,Inputs!$D$33:$D$37) | C4: =SUMPRODUCT('4_Trade'!E4:E8,Inputs!$D$33:$D$37) | D4: =SUMPRODUCT('4_Trade'!F4:F8,Inputs!$D$33:$D$37) | E4: =SUM(B4:D4)
A5: required hedge NetPerp | B5: =-Inputs!$B$18*B4 | C5: =-Inputs!$B$18*C4 | D5: =-Inputs!$B$18*D4 | E5: =SUM(B5:D5)
A6: RESIDUAL exposure (LOOP CLOSURE) | B6: =B5+B4 | C6: =C5+C4 | D6: =D5+D4 | E6: =SUM(B6:D6)
A7: hedge notional $ -> Layer 2b | B7: =ABS(B5)*Inputs!$B$19 | C7: =ABS(C5)*Inputs!$B$19 | D7: =ABS(D5)*Inputs!$B$19 | E7: =SUM(B7:D7)
A8: perp-book exposure used $ | B8: =B7 | C8: =C7 | D8: =D7 | E8: =SUM(B8:D8)
A10: LOOP CLOSED? | B10: =IF(ABS(E6)<0.000001,"YES - residual delta = 0: readback re-hedges exactly the perp book the shapes came from","NO - residual remains (hedge_ratio<1)")

Sheet 8_TraderCircuit
A1: TRADER CIRCUIT — shared perp wallets -> carve -> option position -> close -> carved perp closes back
A3: step | B3: LONG club | C3: SHORT club | D3: TOTAL
A4: 1. perps aggregated into the shared wallet ($ notional) | B4: =Inputs!$B$42 | C4: =Inputs!$B$43 | D4: =B4+C4
A5: 2. club equity posted (= notional x margin_frac) | B5: =B4*Inputs!$B$44 | C5: =C4*Inputs!$B$44 | D5: =B5+C5
A6: 3. CARVE: notional carved out to back options | B6: =B4*Inputs!$B$45 | C6: =C4*Inputs!$B$46 | D6: =B6+C6
A7: 4. equity carved OUT of the perps tab (club.equity -= ) | B7: =B6*Inputs!$B$44 | C7: =C6*Inputs!$B$44 | D7: =B7+C7
A8: 5. perps tab AFTER carve (notional remaining) | B8: =B4-B6 | C8: =C4-C6 | D8: =B8+C8
A9: 6. perps tab AFTER carve (equity remaining) | B9: =B5-B7 | C9: =C5-C7 | D9: =B9+C9
A10: 7. option position backed by the carved slice ($) | B10: =B6 | C10: =C6 | D10: =B10+C10
A11: 8. P&L on the carved slice while open | B11: =B7*Inputs!$B$47 | C11: =C7*Inputs!$B$47 | D11: =B11+C11
A12: 8a. P&L on the carved PERP leg | B12: =B7+B11 | C12: =C7+C11 | D12: =B12+C12
A13: 8b. P&L on the perp-OPTION leg | B13: =B7*Inputs!$B$48 | C13: =C7*Inputs!$B$48 | D13: =B13+C13
A14: 9. CLOSE — carved perp CLOSES; option + its perp P&L CASHED OUT DIRECTLY | B14: =B7+B12+B13 | C14: =C7+C12+C13 | D14: =B14+C14
A15: 10. perps tab after close (equity remaining, carve gone) | B15: =B9 | C15: =C9 | D15: =B15+C15
A17: CONSERVATION CHECK — nothing is created or lost at the exit | B17: =B13 | C17: =C13 | D17: =B17+C17
A18: club equity BEFORE carve | B18: =B5 | C18: =C5 | D18: =B18+C18
A19: perps tab after close (row 15) | B19: =B15 | C19: =C15 | D19: =B19+C19
A20: cash paid out at close (row 14) | B20: =B14 | C20: =C14 | D20: =B20+C20
A21: total P&L both legs (12+13) | B21: =B12+B13 | C21: =C12+C13 | D21: =B21+C21
A22: RESIDUAL = (tab_after + cash_out) - before - P&L (must be 0) | B22: =(B19+B20)-B18-B21 | C22: =(C19+C20)-C18-C21 | D22: =B22+C22
A24: TRADER CIRCUIT CLOSED? | B24: =IF(ABS(D22)<0.000001,"YES - carved perp closes, option + its perp P&L cash out directly, nothing lost","NO - does not reconcile")
A26: Option P&L and its backing perp's P&L settle TOGETHER in one direct cash-out - the exit doorway (Layer 3).
